<?xml version="1.0" ?>
<sdf version='1.6'>
  <world name='default'>
  <model name='mz07'>
    <link name='mz07_link_0'>
      <pose frame=''>0 0 0 0 0 0</pose>
      <inertial>
        <pose frame=''>-0.1 0 0.07 0 -0 0</pose>
        <mass>0</mass>
        <inertia>
          <ixx>0.05</ixx>
          <ixy>0</ixy>
          <ixz>0</ixz>
          <iyy>0.06</iyy>
          <iyz>0</iyz>
          <izz>0.03</izz>
        </inertia>
      </inertial>
      <collision name='mz07_link_0_collision'>
        <pose frame=''>0 0 0 0 0 0</pose>
        <geometry>
          <mesh>
            <scale>1 1 1</scale>
            <uri>stls/mz07/mz07_base.stl</uri>
          </mesh>
        </geometry>
      </collision>
      <visual name='mz07_link_0_visual'>
        <pose frame=''>0 0 0 0 0 0</pose>
        <geometry>
          <mesh>
            <scale>1 1 1</scale>
            <uri>stls/mz07/mz07_base.stl</uri>
          </mesh>
        </geometry>
        <material>
          <ambient>1 0 0 1</ambient>
          <diffuse>0.2 0.2 0.2 1.0</diffuse>
          <specular>0.4 0.4 0.4 1</specular>
          <emissive>0 0 0 0</emissive>
        </material>
      </visual>
    </link>
    <link name='mz07_link_1'>
      <pose frame=''>0 0 0.197 0 0 0</pose>
      <inertial>
        <pose frame=''>0 -0.03 0.12 0 -0 0</pose>
        <mass>4</mass>
        <inertia>
          <ixx>0.1</ixx>
          <ixy>0</ixy>
          <ixz>0</ixz>
          <iyy>0.09</iyy>
          <iyz>0</iyz>
          <izz>0.02</izz>
        </inertia>
      </inertial>
      <collision name='mz07_link_1_collision'>
        <pose frame=''>0 0 0 0 0 0</pose>
        <geometry>
          <mesh>
            <scale>1 1 1</scale>
            <uri>stls/mz07/mz07_link1.stl</uri>
          </mesh>
        </geometry>
      </collision>
      <visual name='mz07_link_1_visual'>
        <pose frame=''>0 0 0 0 0 0</pose>
        <geometry>
          <mesh>
            <scale>1 1 1</scale>
            <uri>stls/mz07/mz07_link1.stl</uri>
          </mesh>
        </geometry>
        <material>
          <ambient>1 0 0 1</ambient>
          <diffuse>1.0 1.0 1.0 1.0</diffuse>
          <specular>0.5 0.5 0.5 1</specular>
          <emissive>0 0 0 0</emissive>
        </material>
      </visual>
    </link>
    <joint name='J0' type='revolute'>
      <child>mz07_link_1</child>
      <parent>mz07_link_0</parent>
      <axis>
        <xyz>0 0 1</xyz>
        <limit>
          <lower>-2.96705981</lower>
          <upper>2.96705981</upper>
          <effort>300</effort>
          <velocity>10</velocity>
        </limit>
        <dynamics>
          <damping>0.5</damping>
          <friction>0</friction>
          <spring_reference>0</spring_reference>
          <spring_stiffness>0</spring_stiffness>
        </dynamics>
      </axis>
    </joint>
    <link name='mz07_link_2'>
      <!-- 0.05 0 0.148 -->
      <pose frame=''>0.05 0 0.345 0 0 0</pose>
      <inertial>
        <pose frame=''>0.0003 0.059 0.042 0 -0 0</pose>
        <mass>4</mass>
        <inertia>
          <ixx>0.05</ixx>
          <ixy>0</ixy>
          <ixz>0</ixz>
          <iyy>0.018</iyy>
          <iyz>0</iyz>
          <izz>0.044</izz>
        </inertia>
      </inertial>
      <collision name='mz07_link_2_collision'>
        <pose frame=''>0 0 0 0 0 0</pose>
        <geometry>
          <mesh>
            <scale>1 1 1</scale>
            <uri>stls/mz07/mz07_link2.stl</uri>
          </mesh>
        </geometry>
      </collision>
      <visual name='mz07_link_2_visual'>
        <pose frame=''>0 0 0 0 0 0</pose>
        <geometry>
          <mesh>
            <scale>1 1 1</scale>
            <uri>stls/mz07/mz07_link2.stl</uri>
          </mesh>
        </geometry>
        <material>
          <ambient>1 0 0 1</ambient>
          <diffuse>1.0 1.0 1.0 1.0</diffuse>
          <specular>0.5 0.5 0.5 1</specular>
          <emissive>0 0 0 0</emissive>
        </material>
      </visual>
    </link>
    <joint name='J1' type='revolute'>
      <child>mz07_link_2</child>
      <parent>mz07_link_1</parent>
      <axis>
        <xyz>0 1 0</xyz>
        <limit>
          <lower>-1.39626344</lower>
          <upper>2.356194555</upper>
          <effort>300</effort>
          <velocity>10</velocity>
        </limit>
        <dynamics>
          <damping>0.5</damping>
          <friction>0</friction>
          <spring_reference>0</spring_reference>
          <spring_stiffness>0</spring_stiffness>
        </dynamics>
      </axis>
    </joint>
    <link name='mz07_link_3'>
      <!-- 0 0 0.33 -->
      <pose frame=''>0.05 0 0.675 0 0 0</pose>
      <inertial>
        <pose frame=''>0 0.03 0.13 0 -0 0</pose>
        <mass>3</mass>
        <inertia>
          <ixx>0.08</ixx>
          <ixy>0</ixy>
          <ixz>0</ixz>
          <iyy>0.075</iyy>
          <iyz>0</iyz>
          <izz>0.01</izz>
        </inertia>
      </inertial>
      <collision name='mz07_link_3_collision'>
        <pose frame=''>0 0 0 0 -1.57 0</pose>
        <geometry>
          <mesh>
            <scale>1 1 1</scale>
            <uri>stls/mz07/mz07_link3.stl</uri>
          </mesh>
        </geometry>
      </collision>
      <visual name='mz07_link_3_visual'>
        <pose frame=''>0 0 0 0 -1.57 0</pose>
        <geometry>
          <mesh>
            <scale>1 1 1</scale>
            <uri>stls/mz07/mz07_link3.stl</uri>
          </mesh>
        </geometry>
        <material>
          <ambient>1 0 0 1</ambient>
          <diffuse>1.0 1.0 1.0 1.0</diffuse>
          <specular>0.5 0.5 0.5 1</specular>
          <emissive>0 0 0 0</emissive>
        </material>
      </visual>
    </link>
    <joint name='J2' type='revolute'>
      <child>mz07_link_3</child>
      <parent>mz07_link_2</parent>
      <axis>
        <xyz>0 1 0</xyz>
        <limit>
          <!-- <lower>-3.14159274</lower>
          <upper>0.802851478</upper> -->
          <lower>-1.57159274</lower>
          <upper>2.372851478</upper>
          <effort>300</effort>
          <velocity>10</velocity>
        </limit>
        <dynamics>
          <damping>0.5</damping>
          <friction>0</friction>
          <spring_reference>0</spring_reference>
          <spring_stiffness>0</spring_stiffness>
        </dynamics>
      </axis>
    </joint>
    <link name='mz07_link_4'>
      <!-- 0.09 0 0.045 -->
      <pose frame=''>0.005 0 0.765 0 0 0</pose>
      <inertial>
        <pose frame=''>0 0.067 0.034 0 -0 0</pose>
        <mass>2.7</mass>
        <inertia>
          <ixx>0.03</ixx>
          <ixy>0</ixy>
          <ixz>0</ixz>
          <iyy>0.01</iyy>
          <iyz>0</iyz>
          <izz>0.029</izz>
        </inertia>
      </inertial>
      <collision name='mz07_link_4_collision'>
        <pose frame=''>0 0 0 0 -1.57 0</pose>
        <geometry>
          <mesh>
            <scale>1 1 1</scale>
            <uri>stls/mz07/mz07_link4.stl</uri>
          </mesh>
        </geometry>
      </collision>
      <visual name='mz07_link_4_visual'>
        <pose frame=''>0 0 0 0 -1.57 0</pose>
        <geometry>
          <mesh>
            <scale>1 1 1</scale>
            <uri>stls/mz07/mz07_link4.stl</uri>
          </mesh>
        </geometry>
        <material>
          <ambient>1 0 0 1</ambient>
          <diffuse>1.0 1.0 1.0 1.0</diffuse>
          <specular>0.5 0.5 0.5 1</specular>
          <emissive>0 0 0 0</emissive>
        </material>
      </visual>
    </link>
    <joint name='J3' type='revolute'>
      <child>mz07_link_4</child>
      <parent>mz07_link_3</parent>
      <axis>
        <xyz>0 0 1</xyz>
        <limit>
          <lower>-3.31612567</lower>
          <upper>3.31612567</upper>
          <effort>300</effort>
          <velocity>10</velocity>
        </limit>
        <dynamics>
          <damping>0.5</damping>
          <friction>0</friction>
          <spring_reference>0</spring_reference>
          <spring_stiffness>0</spring_stiffness>
        </dynamics>
      </axis>
    </joint>
    <link name='mz07_link_5'>
      <!-- 0.25 0 0 -->
      <pose frame=''>0.005 0 1.015 0 0 0</pose>
      <inertial>
        <pose frame=''>0.0001 0.021 0.076 0 -0 0</pose>
        <mass>1.7</mass>
        <inertia>
          <ixx>0.02</ixx>
          <ixy>0</ixy>
          <ixz>0</ixz>
          <iyy>0.018</iyy>
          <iyz>0</iyz>
          <izz>0.005</izz>
        </inertia>
      </inertial>
      <collision name='mz07_link_5_collision'>
        <pose frame=''>0 0 0 0 -1.57 0</pose>
        <geometry>
          <mesh>
            <scale>1 1 1</scale>
            <uri>stls/mz07/mz07_link5.stl</uri>
          </mesh>
        </geometry>
      </collision>
      <visual name='mz07_link_5_visual'>
        <pose frame=''>0 0 0 0 -1.57 0</pose>
        <geometry>
          <mesh>
            <scale>1 1 1</scale>
            <uri>stls/mz07/mz07_link5.stl</uri>
          </mesh>
        </geometry>
        <material>
          <ambient>1 0 0 1</ambient>
          <diffuse>1.0 1.0 1.0 1.0</diffuse>
          <specular>0.5 0.5 0.5 1</specular>
          <emissive>0 0 0 0</emissive>
        </material>
      </visual>
    </link>
    <joint name='J4' type='revolute'>
      <child>mz07_link_5</child>
      <parent>mz07_link_4</parent>
      <axis>
        <xyz>0 1 0</xyz>
        <limit>
          <lower>-2.09439516</lower>
          <upper>2.09439516</upper>
          <effort>300</effort>
          <velocity>10</velocity>
        </limit>
        <dynamics>
          <damping>0.5</damping>
          <friction>0</friction>
          <spring_reference>0</spring_reference>
          <spring_stiffness>0</spring_stiffness>
        </dynamics>
      </axis>
    </joint>
    <link name='mz07_link_6'>
      <!-- 0.063 0 0 -->
      <pose frame=''>0.005 0 1.078 0 0 0</pose>
      <inertial>
        <pose frame=''>0 0.0006 0.0004 0 -0 0</pose>
        <mass>1.8</mass>
        <inertia>
          <ixx>0.005</ixx>
          <ixy>0</ixy>
          <ixz>0</ixz>
          <iyy>0.0036</iyy>
          <iyz>0</iyz>
          <izz>0.0047</izz>
        </inertia>
      </inertial>
      <collision name='mz07_link_6_collision'>
        <pose frame=''>0 0 0 0 -1.57 0</pose>
        <geometry>
          <mesh>
            <scale>1 1 1</scale>
            <uri>stls/mz07/mz07_link6.stl</uri>
          </mesh>
        </geometry>
      </collision>
      <visual name='mz07_link_6_visual'>
        <pose frame=''>0 0 0 0 -1.57 0</pose>
        <geometry>
          <mesh>
            <scale>1 1 1</scale>
            <uri>stls/mz07/mz07_link6.stl</uri>
          </mesh>
        </geometry>
        <material>
          <ambient>1 0 0 1</ambient>
          <diffuse>0.1 0.1 0.1 1.0</diffuse>
          <specular>0.5 0.5 0.5 1</specular>
          <emissive>0 0 0 0</emissive>
        </material>
      </visual>
    </link>
    <joint name='J5' type='revolute'>
      <child>mz07_link_6</child>
      <parent>mz07_link_5</parent>
      <axis>
        <xyz>0 0 1</xyz>
        <limit>
          <lower>-6.28318548</lower>
          <upper>6.28318548</upper>
          <effort>300</effort>
          <velocity>10</velocity>
        </limit>
        <dynamics>
          <damping>0.5</damping>
          <friction>0</friction>
          <spring_reference>0</spring_reference>
          <spring_stiffness>0</spring_stiffness>
        </dynamics>
      </axis>
    </joint>
  </model>
</world>
</sdf>
