<mujoco>
	<body mocap="true" name="robot0:mocap" pos="0 0 0">
		<geom conaffinity="0" contype="0" pos="0 0 0" rgba="0 0.5 0 0.7" size="0.005 0.005 0.005" type="box"></geom>
		<geom conaffinity="0" contype="0" pos="0 0 0" rgba="0 0.5 0 0.1" size="1 0.005 0.005" type="box"></geom>
		<geom conaffinity="0" contype="0" pos="0 0 0" rgba="0 0.5 0 0.1" size="0.005 1 0.001" type="box"></geom>
		<geom conaffinity="0" contype="0" pos="0 0 0" rgba="0 0.5 0 0.1" size="0.005 0.005 1" type="box"></geom>
	</body>
	<body childclass="robot0:fetch" name="robot0:base_link" pos="0.2869 0.2641 0">
		<joint armature="0.0001" axis="1 0 0" damping="1e+11" name="robot0:slide0" pos="0 0 0" type="slide"></joint>
		<joint armature="0.0001" axis="0 1 0" damping="1e+11" name="robot0:slide1" pos="0 0 0" type="slide"></joint>
		<joint armature="0.0001" axis="0 0 1" damping="1e+11" name="robot0:slide2" pos="0 0 0" type="slide"></joint>
		<geom mesh="robot0:base_link" name="robot0:base_link" material="robot0:base_mat" class="robot0:grey"></geom>
		<!-- link1 -->
		<body name="robot0:shoulder_pan_link" pos="0 0 0.197">
			<joint axis="0 0 1" name="robot0:shoulder_pan_joint" range="-2.96705981 2.96705981"></joint>
			<geom mesh="robot0:shoulder_pan_link" name="robot0:shoulder_pan_link" material="robot0:arm_mat"></geom>
			<!-- link2 -->
			<body name="robot0:upperarm_roll_link" pos="0.05 0 0.148">
				<joint axis="0 1 0" name="robot0:upperarm_roll_joint" range="-1.39626344 2.356194555"></joint>
				<geom mesh="robot0:upperarm_roll_link" name="robot0:upperarm_roll_link" material="robot0:arm_mat"></geom>
				<!-- link3 -->
				<body name="robot0:elbow_flex_link" pos="0 0 0.33">
					<joint axis="0 1 0" name="robot0:elbow_flex_joint" range="-3.14159274 0.802851478"></joint>
					<geom mesh="robot0:elbow_flex_link" name="robot0:elbow_flex_link" material="robot0:arm_mat"></geom>
					<!-- link4 -->
					<body name="robot0:forearm_roll_link" pos="0.09 0 0.045">
						<joint axis="1 0 0" name="robot0:forearm_roll_joint" range="-3.31612567 3.31612567"></joint>
						<geom mesh="robot0:forearm_roll_link" name="robot0:forearm_roll_link" material="robot0:arm_mat"></geom>
						<!-- link5 -->
						<body name="robot0:wrist_flex_link" pos="0.25 0 0">
							<joint axis="0 1 0" name="robot0:wrist_flex_joint" range="-2.09439516 2.09439516"></joint>
							<geom mesh="robot0:wrist_flex_link" name="robot0:wrist_flex_link" material="robot0:arm_mat"></geom>
							<!-- link6 -->
							<body name="robot0:wrist_roll_link" pos="0.063 0 0">
								<joint axis="1 0 0" name="robot0:wrist_roll_joint" range="-6.28318548 6.28318548"></joint>
								<geom mesh="robot0:wrist_roll_link" name="robot0:wrist_roll_link" material="robot0:arm_mat" class="robot0:grey"></geom>
								<!-- girpper -->
								<body euler="0 0 0" name="robot0:gripper_link" pos="0.1664 0 0">
									<inertial diaginertia="0.0024 0.0019 0.0013" mass="1.5175" pos="-0.09 -0.0001 -0.0017" quat="0 0.7071 0 0.7071"></inertial>
									<geom mesh="robot0:gripper_link" name="robot0:gripper_link" material="robot0:gripper_mat"></geom>
									<body name="robot0:gripper_camera_link" pos="0.055 0 0.0225">
										<body name="robot0:gripper_camera_rgb_frame" pos="0 0.02 0">
											<body name="robot0:gripper_camera_rgb_optical_frame" pos="0 0 0" quat="0.5 -0.5 0.5 -0.5">
												<camera euler="3.1415 0 0" fovy="50" name="gripper_camera_rgb" pos="0 0 0"></camera>
											</body>
										</body>
										<body name="robot0:gripper_camera_depth_frame" pos="0 0.045 0">
											<body name="robot0:gripper_camera_depth_optical_frame" pos="0 0 0" quat="0.5 -0.5 0.5 -0.5"></body>
										</body>
									</body>

									<body childclass="robot0:fetchGripper" name="robot0:r_gripper_finger_link" pos="0 0.0159 0">
										<inertial diaginertia="0.1 0.1 0.1" mass="4" pos="-0.01 0 0"></inertial>
										<joint axis="0 1 0" name="robot0:r_gripper_finger_joint" range="0 0.05"></joint>
										<geom pos="0 -0.008 0" size="0.0385 0.007 0.0135" type="box" name="robot0:r_gripper_finger_link" material="robot0:gripper_finger_mat" condim="4" friction="1 0.05 0.01"></geom>
									</body>
									<body childclass="robot0:fetchGripper" name="robot0:l_gripper_finger_link" pos="0 -0.0159 0">
										<inertial diaginertia="0.1 0.1 0.1" mass="4" pos="-0.01 0 0"></inertial>
										<joint axis="0 -1 0" name="robot0:l_gripper_finger_joint" range="0 0.05"></joint>
										<geom pos="0 0.008 0" size="0.0385 0.007 0.0135" type="box" name="robot0:l_gripper_finger_link" material="robot0:gripper_finger_mat" condim="4" friction="1 0.05 0.01"></geom>
									</body>
									<site name="robot0:grip" pos="0.02 0 0" rgba="0 0 0 0" size="0.02 0.02 0.02"></site>
								</body>
							</body>
						</body>
					</body>
				</body>
			</body>
		</body>
	</body>
</mujoco>
